2025-07-24 22:24:40,872 - __main__ - INFO - 投稿机器人启动中...
2025-07-24 22:24:41,142 - httpx - INFO - HTTP Request: POST https://api.telegram.org/botYOUR_SUBMISSION_BOT_TOKEN/getMe "HTTP/1.1 404 Not Found"
2025-07-24 22:24:41,143 - telegram.ext - ERROR - Network Retry Loop (Bootstrap Initialize Application): Invalid token. Aborting retry loop.
Traceback (most recent call last):
  File "/workspace/venv/lib/python3.13/site-packages/telegram/_bot.py", line 845, in initialize
    await self.get_me()
  File "/workspace/venv/lib/python3.13/site-packages/telegram/ext/_extbot.py", line 1981, in get_me
    return await super().get_me(
           ^^^^^^^^^^^^^^^^^^^^^
    ...<5 lines>...
    )
    ^
  File "/workspace/venv/lib/python3.13/site-packages/telegram/_bot.py", line 976, in get_me
    result = await self._post(
             ^^^^^^^^^^^^^^^^^
    ...<6 lines>...
    )
    ^
  File "/workspace/venv/lib/python3.13/site-packages/telegram/_bot.py", line 698, in _post
    return await self._do_post(
           ^^^^^^^^^^^^^^^^^^^^
    ...<6 lines>...
    )
    ^
  File "/workspace/venv/lib/python3.13/site-packages/telegram/ext/_extbot.py", line 370, in _do_post
    return await super()._do_post(
           ^^^^^^^^^^^^^^^^^^^^^^^
    ...<6 lines>...
    )
    ^
  File "/workspace/venv/lib/python3.13/site-packages/telegram/_bot.py", line 727, in _do_post
    result = await request.post(
             ^^^^^^^^^^^^^^^^^^^
    ...<6 lines>...
    )
    ^
  File "/workspace/venv/lib/python3.13/site-packages/telegram/request/_baserequest.py", line 197, in post
    result = await self._request_wrapper(
             ^^^^^^^^^^^^^^^^^^^^^^^^^^^^
    ...<7 lines>...
    )
    ^
  File "/workspace/venv/lib/python3.13/site-packages/telegram/request/_baserequest.py", line 374, in _request_wrapper
    raise exception
telegram.error.InvalidToken: Not Found

The above exception was the direct cause of the following exception:

Traceback (most recent call last):
  File "/workspace/venv/lib/python3.13/site-packages/telegram/ext/_utils/networkloop.py", line 115, in network_retry_loop
    if not await do_action():
           ^^^^^^^^^^^^^^^^^
  File "/workspace/venv/lib/python3.13/site-packages/telegram/ext/_utils/networkloop.py", line 93, in do_action
    return await action_cb()
           ^^^^^^^^^^^^^^^^^
  File "/workspace/venv/lib/python3.13/site-packages/telegram/ext/_application.py", line 489, in initialize
    await self.bot.initialize()
  File "/workspace/venv/lib/python3.13/site-packages/telegram/ext/_extbot.py", line 316, in initialize
    await super().initialize()
  File "/workspace/venv/lib/python3.13/site-packages/telegram/_bot.py", line 847, in initialize
    raise InvalidToken(f"The token `{self._token}` was rejected by the server.") from exc
telegram.error.InvalidToken: The token `YOUR_SUBMISSION_BOT_TOKEN` was rejected by the server.
